No sentence-transformers model found with name neulab/codebert-cpp. Creating a new one with mean pooling.
Some weights of RobertaModel were not initialized from the model checkpoint at neulab/codebert-cpp and are newly initialized: ['roberta.pooler.dense.bias', 'roberta.pooler.dense.weight']
You should probably TRAIN this model on a down-stream task to be able to use it for predictions and inference.
False
False

Running evaluation for model: gpt-4o-mini
base
17_graph_highest_degree
base
15_graph_edge_count
base
18_graph_count_components
base
16_graph_largest_component
base
19_graph_shortest_path
base
21_histogram_bin_0-100
base
23_histogram_first_letter_counts
base
20_histogram_pixel_histogram
base
24_histogram_count_quartile
base
22_histogram_count_quadrants
base
34_scan_largest_contiguous_subarray_sum
base
33_scan_reverse_prefix_sum
base
32_scan_sum_of_prefix_sum_array
base
31_scan_scan_with_min_function
base
30_scan_prefix_sum
base
59_transform_map_function
base
55_transform_relu
base
56_transform_negate_odds
base
57_transform_inverse_offset
base
58_transform_squaring
base
48_sparse_la_sparse_axpy
base
49_sparse_la_sparse_lu_decomp
base
46_sparse_la_spmm
base
45_sparse_la_sparse_solve
base
47_sparse_la_spmv
base
25_reduce_xor
base
27_reduce_average
base
28_reduce_smallest_odd_number
base
29_reduce_sum_of_min_of_pairs
base
26_reduce_product_of_inverses
base
08_fft_split_fft
base
06_fft_dft
base
09_fft_fft_out_of_place
base
请求失败
Connection error.
请求失败
Connection error.
请求失败
Connection error.
请求失败
Connection error.
请求失败
Connection error.
请求失败
Connection error.
请求失败
Connection error.
请求失败
Connection error.
请求失败
Connection error.
请求失败
Connection error.
Traceback (most recent call last):
  File "/public/home/xwhuang/anaconda3/envs/eval/lib/python3.10/site-packages/httpx/_transports/default.py", line 101, in map_httpcore_exceptions
    yield
  File "/public/home/xwhuang/anaconda3/envs/eval/lib/python3.10/site-packages/httpx/_transports/default.py", line 250, in handle_request
    resp = self._pool.handle_request(req)
  File "/public/home/xwhuang/anaconda3/envs/eval/lib/python3.10/site-packages/httpcore/_sync/connection_pool.py", line 256, in handle_request
    raise exc from None
  File "/public/home/xwhuang/anaconda3/envs/eval/lib/python3.10/site-packages/httpcore/_sync/connection_pool.py", line 236, in handle_request
    response = connection.handle_request(
  File "/public/home/xwhuang/anaconda3/envs/eval/lib/python3.10/site-packages/httpcore/_sync/http_proxy.py", line 316, in handle_request
    stream = stream.start_tls(**kwargs)
  File "/public/home/xwhuang/anaconda3/envs/eval/lib/python3.10/site-packages/httpcore/_sync/http11.py", line 376, in start_tls
    return self._stream.start_tls(ssl_context, server_hostname, timeout)
  File "/public/home/xwhuang/anaconda3/envs/eval/lib/python3.10/site-packages/httpcore/_backends/sync.py", line 154, in start_tls
    with map_exceptions(exc_map):
  File "/public/home/xwhuang/anaconda3/envs/eval/lib/python3.10/contextlib.py", line 153, in __exit__
    self.gen.throw(typ, value, traceback)
  File "/public/home/xwhuang/anaconda3/envs/eval/lib/python3.10/site-packages/httpcore/_exceptions.py", line 14, in map_exceptions
    raise to_exc(exc) from exc
httpcore.ConnectError: [SSL: CERTIFICATE_VERIFY_FAILED] certificate verify failed: Hostname mismatch, certificate is not valid for 'api.openai.com'. (_ssl.c:1007)

The above exception was the direct cause of the following exception:

Traceback (most recent call last):
  File "/public/home/xwhuang/anaconda3/envs/eval/lib/python3.10/site-packages/openai/_base_client.py", line 993, in _request
    response = self._client.send(
  File "/public/home/xwhuang/anaconda3/envs/eval/lib/python3.10/site-packages/httpx/_client.py", line 914, in send
    response = self._send_handling_auth(
  File "/public/home/xwhuang/anaconda3/envs/eval/lib/python3.10/site-packages/httpx/_client.py", line 942, in _send_handling_auth
    response = self._send_handling_redirects(
  File "/public/home/xwhuang/anaconda3/envs/eval/lib/python3.10/site-packages/httpx/_client.py", line 979, in _send_handling_redirects
    response = self._send_single_request(request)
  File "/public/home/xwhuang/anaconda3/envs/eval/lib/python3.10/site-packages/httpx/_client.py", line 1014, in _send_single_request
    response = transport.handle_request(request)
  File "/public/home/xwhuang/anaconda3/envs/eval/lib/python3.10/site-packages/httpx/_transports/default.py", line 249, in handle_request
    with map_httpcore_exceptions():
  File "/public/home/xwhuang/anaconda3/envs/eval/lib/python3.10/contextlib.py", line 153, in __exit__
    self.gen.throw(typ, value, traceback)
  File "/public/home/xwhuang/anaconda3/envs/eval/lib/python3.10/site-packages/httpx/_transports/default.py", line 118, in map_httpcore_exceptions
    raise mapped_exc(message) from exc
httpx.ConnectError: [SSL: CERTIFICATE_VERIFY_FAILED] certificate verify failed: Hostname mismatch, certificate is not valid for 'api.openai.com'. (_ssl.c:1007)

The above exception was the direct cause of the following exception:

Traceback (most recent call last):
  File "/public/home/xwhuang/LLM4PP/model_eval/evaluation/evalution_2_12.py", line 120, in get_response_with_retry
    response = chatAPI.get_response(model, messages, json_format=False)
  File "/public/home/xwhuang/LLM4PP/model_eval/evaluation/fastcoder/chatapi.py", line 148, in get_response
    completion = self.client.chat.completions.create(model=model,
  File "/public/home/xwhuang/anaconda3/envs/eval/lib/python3.10/site-packages/openai/_utils/_utils.py", line 275, in wrapper
    return func(*args, **kwargs)
  File "/public/home/xwhuang/anaconda3/envs/eval/lib/python3.10/site-packages/openai/resources/chat/completions.py", line 859, in create
    return self._post(
  File "/public/home/xwhuang/anaconda3/envs/eval/lib/python3.10/site-packages/openai/_base_client.py", line 1280, in post
    return cast(ResponseT, self.request(cast_to, opts, stream=stream, stream_cls=stream_cls))
  File "/public/home/xwhuang/anaconda3/envs/eval/lib/python3.10/site-packages/openai/_base_client.py", line 957, in request
    return self._request(
  File "/public/home/xwhuang/anaconda3/envs/eval/lib/python3.10/site-packages/openai/_base_client.py", line 1017, in _request
    return self._retry_request(
  File "/public/home/xwhuang/anaconda3/envs/eval/lib/python3.10/site-packages/openai/_base_client.py", line 1095, in _retry_request
    return self._request(
  File "/public/home/xwhuang/anaconda3/envs/eval/lib/python3.10/site-packages/openai/_base_client.py", line 1017, in _request
    return self._retry_request(
  File "/public/home/xwhuang/anaconda3/envs/eval/lib/python3.10/site-packages/openai/_base_client.py", line 1095, in _retry_request
    return self._request(
  File "/public/home/xwhuang/anaconda3/envs/eval/lib/python3.10/site-packages/openai/_base_client.py", line 1027, in _request
    raise APIConnectionError(request=request) from err
openai.APIConnectionError: Connection error.

During handling of the above exception, another exception occurred:

Traceback (most recent call last):
  File "/public/home/xwhuang/anaconda3/envs/eval/lib/python3.10/site-packages/tenacity/__init__.py", line 478, in __call__
    result = fn(*args, **kwargs)
  File "/public/home/xwhuang/LLM4PP/model_eval/evaluation/evalution_2_12.py", line 130, in get_response_with_retry
    sleep(3)
NameError: name 'sleep' is not defined

The above exception was the direct cause of the following exception:

Traceback (most recent call last):
  File "/public/home/xwhuang/LLM4PP/model_eval/evaluation/evalution_2_12.py", line 621, in <module>
    main()
  File "/public/home/xwhuang/LLM4PP/model_eval/evaluation/evalution_2_12.py", line 403, in main
    optimized_code = get_response_with_retry(chatAPI, 'gpt-4o-mini', messages, json_format=True)
  File "/public/home/xwhuang/anaconda3/envs/eval/lib/python3.10/site-packages/tenacity/__init__.py", line 336, in wrapped_f
    return copy(f, *args, **kw)
  File "/public/home/xwhuang/anaconda3/envs/eval/lib/python3.10/site-packages/tenacity/__init__.py", line 475, in __call__
    do = self.iter(retry_state=retry_state)
  File "/public/home/xwhuang/anaconda3/envs/eval/lib/python3.10/site-packages/tenacity/__init__.py", line 376, in iter
    result = action(retry_state)
  File "/public/home/xwhuang/anaconda3/envs/eval/lib/python3.10/site-packages/tenacity/__init__.py", line 419, in exc_check
    raise retry_exc from fut.exception()
tenacity.RetryError: RetryError[<Future at 0x2aec29713790 state=finished raised NameError>]
